2020-02-20 09:43:25,094 ERROR: Exception on /status [GET] [in /Users/giladspitzer/PycharmProjects/CAPSTONE/venv/lib/python3.8/site-packages/flask/app.py:1890]
Traceback (most recent call last):
  File "/Users/giladspitzer/PycharmProjects/CAPSTONE/venv/lib/python3.8/site-packages/sqlalchemy/engine/base.py", line 1245, in _execute_context
    self.dialect.do_execute(
  File "/Users/giladspitzer/PycharmProjects/CAPSTONE/venv/lib/python3.8/site-packages/sqlalchemy/engine/default.py", line 581, in do_execute
    cursor.execute(statement, parameters)
sqlite3.OperationalError: database is locked

The above exception was the direct cause of the following exception:

Traceback (most recent call last):
  File "/Users/giladspitzer/PycharmProjects/CAPSTONE/venv/lib/python3.8/site-packages/flask/app.py", line 2446, in wsgi_app
    response = self.full_dispatch_request()
  File "/Users/giladspitzer/PycharmProjects/CAPSTONE/venv/lib/python3.8/site-packages/flask/app.py", line 1951, in full_dispatch_request
    rv = self.handle_user_exception(e)
  File "/Users/giladspitzer/PycharmProjects/CAPSTONE/venv/lib/python3.8/site-packages/flask/app.py", line 1820, in handle_user_exception
    reraise(exc_type, exc_value, tb)
  File "/Users/giladspitzer/PycharmProjects/CAPSTONE/venv/lib/python3.8/site-packages/flask/_compat.py", line 39, in reraise
    raise value
  File "/Users/giladspitzer/PycharmProjects/CAPSTONE/venv/lib/python3.8/site-packages/flask/app.py", line 1947, in full_dispatch_request
    rv = self.preprocess_request()
  File "/Users/giladspitzer/PycharmProjects/CAPSTONE/venv/lib/python3.8/site-packages/flask/app.py", line 2241, in preprocess_request
    rv = func()
  File "/Users/giladspitzer/PycharmProjects/CAPSTONE/app/routes.py", line 61, in before_request
    db.session.commit()
  File "/Users/giladspitzer/PycharmProjects/CAPSTONE/venv/lib/python3.8/site-packages/sqlalchemy/orm/scoping.py", line 162, in do
    return getattr(self.registry(), name)(*args, **kwargs)
  File "/Users/giladspitzer/PycharmProjects/CAPSTONE/venv/lib/python3.8/site-packages/sqlalchemy/orm/session.py", line 1027, in commit
    self.transaction.commit()
  File "/Users/giladspitzer/PycharmProjects/CAPSTONE/venv/lib/python3.8/site-packages/sqlalchemy/orm/session.py", line 494, in commit
    self._prepare_impl()
  File "/Users/giladspitzer/PycharmProjects/CAPSTONE/venv/lib/python3.8/site-packages/sqlalchemy/orm/session.py", line 473, in _prepare_impl
    self.session.flush()
  File "/Users/giladspitzer/PycharmProjects/CAPSTONE/venv/lib/python3.8/site-packages/sqlalchemy/orm/session.py", line 2470, in flush
    self._flush(objects)
  File "/Users/giladspitzer/PycharmProjects/CAPSTONE/venv/lib/python3.8/site-packages/sqlalchemy/orm/session.py", line 2608, in _flush
    transaction.rollback(_capture_exception=True)
  File "/Users/giladspitzer/PycharmProjects/CAPSTONE/venv/lib/python3.8/site-packages/sqlalchemy/util/langhelpers.py", line 68, in __exit__
    compat.reraise(exc_type, exc_value, exc_tb)
  File "/Users/giladspitzer/PycharmProjects/CAPSTONE/venv/lib/python3.8/site-packages/sqlalchemy/util/compat.py", line 153, in reraise
    raise value
  File "/Users/giladspitzer/PycharmProjects/CAPSTONE/venv/lib/python3.8/site-packages/sqlalchemy/orm/session.py", line 2568, in _flush
    flush_context.execute()
  File "/Users/giladspitzer/PycharmProjects/CAPSTONE/venv/lib/python3.8/site-packages/sqlalchemy/orm/unitofwork.py", line 422, in execute
    rec.execute(self)
  File "/Users/giladspitzer/PycharmProjects/CAPSTONE/venv/lib/python3.8/site-packages/sqlalchemy/orm/unitofwork.py", line 586, in execute
    persistence.save_obj(
  File "/Users/giladspitzer/PycharmProjects/CAPSTONE/venv/lib/python3.8/site-packages/sqlalchemy/orm/persistence.py", line 230, in save_obj
    _emit_update_statements(
  File "/Users/giladspitzer/PycharmProjects/CAPSTONE/venv/lib/python3.8/site-packages/sqlalchemy/orm/persistence.py", line 995, in _emit_update_statements
    c = cached_connections[connection].execute(
  File "/Users/giladspitzer/PycharmProjects/CAPSTONE/venv/lib/python3.8/site-packages/sqlalchemy/engine/base.py", line 982, in execute
    return meth(self, multiparams, params)
  File "/Users/giladspitzer/PycharmProjects/CAPSTONE/venv/lib/python3.8/site-packages/sqlalchemy/sql/elements.py", line 287, in _execute_on_connection
    return connection._execute_clauseelement(self, multiparams, params)
  File "/Users/giladspitzer/PycharmProjects/CAPSTONE/venv/lib/python3.8/site-packages/sqlalchemy/engine/base.py", line 1095, in _execute_clauseelement
    ret = self._execute_context(
  File "/Users/giladspitzer/PycharmProjects/CAPSTONE/venv/lib/python3.8/site-packages/sqlalchemy/engine/base.py", line 1249, in _execute_context
    self._handle_dbapi_exception(
  File "/Users/giladspitzer/PycharmProjects/CAPSTONE/venv/lib/python3.8/site-packages/sqlalchemy/engine/base.py", line 1476, in _handle_dbapi_exception
    util.raise_from_cause(sqlalchemy_exception, exc_info)
  File "/Users/giladspitzer/PycharmProjects/CAPSTONE/venv/lib/python3.8/site-packages/sqlalchemy/util/compat.py", line 398, in raise_from_cause
    reraise(type(exception), exception, tb=exc_tb, cause=cause)
  File "/Users/giladspitzer/PycharmProjects/CAPSTONE/venv/lib/python3.8/site-packages/sqlalchemy/util/compat.py", line 152, in reraise
    raise value.with_traceback(tb)
  File "/Users/giladspitzer/PycharmProjects/CAPSTONE/venv/lib/python3.8/site-packages/sqlalchemy/engine/base.py", line 1245, in _execute_context
    self.dialect.do_execute(
  File "/Users/giladspitzer/PycharmProjects/CAPSTONE/venv/lib/python3.8/site-packages/sqlalchemy/engine/default.py", line 581, in do_execute
    cursor.execute(statement, parameters)
sqlalchemy.exc.OperationalError: (sqlite3.OperationalError) database is locked
[SQL: UPDATE user SET last_seen=? WHERE user.id = ?]
[parameters: ('2020-02-20 17:43:19.930484', 1)]
(Background on this error at: http://sqlalche.me/e/e3q8)
