2020-03-15 12:45:01,684 ERROR: Exception on /retrieve_data [GET] [in /Users/giladspitzer/PycharmProjects/CAPSTONE/venv/lib/python3.8/site-packages/flask/app.py:1890]
Traceback (most recent call last):
  File "/Users/giladspitzer/PycharmProjects/CAPSTONE/venv/lib/python3.8/site-packages/flask/app.py", line 2446, in wsgi_app
    response = self.full_dispatch_request()
  File "/Users/giladspitzer/PycharmProjects/CAPSTONE/venv/lib/python3.8/site-packages/flask/app.py", line 1951, in full_dispatch_request
    rv = self.handle_user_exception(e)
  File "/Users/giladspitzer/PycharmProjects/CAPSTONE/venv/lib/python3.8/site-packages/flask/app.py", line 1820, in handle_user_exception
    reraise(exc_type, exc_value, tb)
  File "/Users/giladspitzer/PycharmProjects/CAPSTONE/venv/lib/python3.8/site-packages/flask/_compat.py", line 39, in reraise
    raise value
  File "/Users/giladspitzer/PycharmProjects/CAPSTONE/venv/lib/python3.8/site-packages/flask/app.py", line 1949, in full_dispatch_request
    rv = self.dispatch_request()
  File "/Users/giladspitzer/PycharmProjects/CAPSTONE/venv/lib/python3.8/site-packages/flask/app.py", line 1935, in dispatch_request
    return self.view_functions[rule.endpoint](**req.view_args)
  File "/Users/giladspitzer/PycharmProjects/CAPSTONE/venv/lib/python3.8/site-packages/flask_login/utils.py", line 272, in decorated_view
    return func(*args, **kwargs)
  File "/Users/giladspitzer/PycharmProjects/CAPSTONE/app/routes.py", line 333, in retrieve_data
    current_user.update_assignments()
  File "/Users/giladspitzer/PycharmProjects/CAPSTONE/app/models.py", line 170, in update_assignments
    assignments = sc.get_section_assignments([self.api_key, self.api_secret], s.schoology_id)
  File "/Users/giladspitzer/PycharmProjects/CAPSTONE/app/apiclean.py", line 24, in get_section_assignments
    section_assignments = authenticate(data[0], data[1]).get_assignments(section_id)
  File "/Users/giladspitzer/PycharmProjects/CAPSTONE/app/schoologyapi/api.py", line 845, in get_assignments
    return [Assignment(raw) for raw in self._get('sections/%s/assignments' % section_id)['assignment']]
KeyError: 'assignment'
2020-03-15 12:45:01,692 ERROR: Exception on /retrieve_data [GET] [in /Users/giladspitzer/PycharmProjects/CAPSTONE/venv/lib/python3.8/site-packages/flask/app.py:1890]
Traceback (most recent call last):
  File "/Users/giladspitzer/PycharmProjects/CAPSTONE/venv/lib/python3.8/site-packages/flask/app.py", line 2446, in wsgi_app
    response = self.full_dispatch_request()
  File "/Users/giladspitzer/PycharmProjects/CAPSTONE/venv/lib/python3.8/site-packages/flask/app.py", line 1951, in full_dispatch_request
    rv = self.handle_user_exception(e)
  File "/Users/giladspitzer/PycharmProjects/CAPSTONE/venv/lib/python3.8/site-packages/flask/app.py", line 1820, in handle_user_exception
    reraise(exc_type, exc_value, tb)
  File "/Users/giladspitzer/PycharmProjects/CAPSTONE/venv/lib/python3.8/site-packages/flask/_compat.py", line 39, in reraise
    raise value
  File "/Users/giladspitzer/PycharmProjects/CAPSTONE/venv/lib/python3.8/site-packages/flask/app.py", line 1949, in full_dispatch_request
    rv = self.dispatch_request()
  File "/Users/giladspitzer/PycharmProjects/CAPSTONE/venv/lib/python3.8/site-packages/flask/app.py", line 1935, in dispatch_request
    return self.view_functions[rule.endpoint](**req.view_args)
  File "/Users/giladspitzer/PycharmProjects/CAPSTONE/venv/lib/python3.8/site-packages/flask_login/utils.py", line 272, in decorated_view
    return func(*args, **kwargs)
  File "/Users/giladspitzer/PycharmProjects/CAPSTONE/app/routes.py", line 333, in retrieve_data
    current_user.update_assignments()
  File "/Users/giladspitzer/PycharmProjects/CAPSTONE/app/models.py", line 201, in update_assignments
    name = person.name_display
AttributeError: 'User' object has no attribute 'name_display'
2020-03-15 12:45:46,751 ERROR: Exception on /retrieve_data [GET] [in /Users/giladspitzer/PycharmProjects/CAPSTONE/venv/lib/python3.8/site-packages/flask/app.py:1890]
Traceback (most recent call last):
  File "/Users/giladspitzer/PycharmProjects/CAPSTONE/venv/lib/python3.8/site-packages/flask/app.py", line 2446, in wsgi_app
    response = self.full_dispatch_request()
  File "/Users/giladspitzer/PycharmProjects/CAPSTONE/venv/lib/python3.8/site-packages/flask/app.py", line 1951, in full_dispatch_request
    rv = self.handle_user_exception(e)
  File "/Users/giladspitzer/PycharmProjects/CAPSTONE/venv/lib/python3.8/site-packages/flask/app.py", line 1820, in handle_user_exception
    reraise(exc_type, exc_value, tb)
  File "/Users/giladspitzer/PycharmProjects/CAPSTONE/venv/lib/python3.8/site-packages/flask/_compat.py", line 39, in reraise
    raise value
  File "/Users/giladspitzer/PycharmProjects/CAPSTONE/venv/lib/python3.8/site-packages/flask/app.py", line 1949, in full_dispatch_request
    rv = self.dispatch_request()
  File "/Users/giladspitzer/PycharmProjects/CAPSTONE/venv/lib/python3.8/site-packages/flask/app.py", line 1935, in dispatch_request
    return self.view_functions[rule.endpoint](**req.view_args)
  File "/Users/giladspitzer/PycharmProjects/CAPSTONE/venv/lib/python3.8/site-packages/flask_login/utils.py", line 272, in decorated_view
    return func(*args, **kwargs)
  File "/Users/giladspitzer/PycharmProjects/CAPSTONE/app/routes.py", line 333, in retrieve_data
    current_user.update_assignments()
  File "/Users/giladspitzer/PycharmProjects/CAPSTONE/app/models.py", line 197, in update_assignments
    comments = sc.get_assignment_comments([self.api_key, self.api_secret], s.id, a.id)
  File "/Users/giladspitzer/PycharmProjects/CAPSTONE/app/apiclean.py", line 43, in get_assignment_comments
    return authenticate(data[0], data[1]).get_assignment_comments(sectionid, assignmentid)
  File "/Users/giladspitzer/PycharmProjects/CAPSTONE/app/schoologyapi/api.py", line 852, in get_assignment_comments
    return [Assignment(raw) for raw in self._get('sections/%s/assignments/%s/comments' % (section_id, assignment_id))['comment']]
KeyError: 'comment'
2020-03-15 21:49:16,314 INFO: SchoologyLinked startup [in /Users/giladspitzer/PycharmProjects/CAPSTONE/app/__init__.py:58]
2020-03-15 22:28:36,092 INFO: SchoologyLinked startup [in /Users/giladspitzer/PycharmProjects/CAPSTONE/app/__init__.py:58]
2020-03-15 22:28:58,944 INFO: SchoologyLinked startup [in /Users/giladspitzer/PycharmProjects/CAPSTONE/app/__init__.py:58]
2020-03-15 22:30:07,997 INFO: SchoologyLinked startup [in /Users/giladspitzer/PycharmProjects/CAPSTONE/app/__init__.py:58]
2020-03-15 22:30:46,888 INFO: SchoologyLinked startup [in /Users/giladspitzer/PycharmProjects/CAPSTONE/app/__init__.py:58]
2020-03-15 23:53:56,035 ERROR: Exception on /sync_all/SyncAllPassword123 [GET] [in /Users/giladspitzer/PycharmProjects/CAPSTONE/venv/lib/python3.8/site-packages/flask/app.py:1890]
Traceback (most recent call last):
  File "/Users/giladspitzer/PycharmProjects/CAPSTONE/venv/lib/python3.8/site-packages/flask/app.py", line 2446, in wsgi_app
    response = self.full_dispatch_request()
  File "/Users/giladspitzer/PycharmProjects/CAPSTONE/venv/lib/python3.8/site-packages/flask/app.py", line 1951, in full_dispatch_request
    rv = self.handle_user_exception(e)
  File "/Users/giladspitzer/PycharmProjects/CAPSTONE/venv/lib/python3.8/site-packages/flask/app.py", line 1820, in handle_user_exception
    reraise(exc_type, exc_value, tb)
  File "/Users/giladspitzer/PycharmProjects/CAPSTONE/venv/lib/python3.8/site-packages/flask/_compat.py", line 39, in reraise
    raise value
  File "/Users/giladspitzer/PycharmProjects/CAPSTONE/venv/lib/python3.8/site-packages/flask/app.py", line 1949, in full_dispatch_request
    rv = self.dispatch_request()
  File "/Users/giladspitzer/PycharmProjects/CAPSTONE/venv/lib/python3.8/site-packages/flask/app.py", line 1935, in dispatch_request
    return self.view_functions[rule.endpoint](**req.view_args)
  File "/Users/giladspitzer/PycharmProjects/CAPSTONE/venv/lib/python3.8/site-packages/flask_login/utils.py", line 272, in decorated_view
    return func(*args, **kwargs)
  File "/Users/giladspitzer/PycharmProjects/CAPSTONE/app/routes.py", line 29, in sync_all
    user.update()
  File "/Users/giladspitzer/PycharmProjects/CAPSTONE/app/models.py", line 351, in update
    self.update_grades()
  File "/Users/giladspitzer/PycharmProjects/CAPSTONE/app/models.py", line 197, in update_assignments
    for comment in comments:
  File "/Users/giladspitzer/PycharmProjects/CAPSTONE/app/apiclean.py", line 43, in get_assignment_comments
    return authenticate(data[0], data[1]).get_assignment_comments(sectionid, assignmentid)
  File "/Users/giladspitzer/PycharmProjects/CAPSTONE/app/schoologyapi/api.py", line 853, in get_assignment_comments
    return [Assignment(raw) for raw in self._get('sections/%s/assignments/%s/comments' % (section_id, assignment_id))['comment']]
KeyError: 'comment'
2020-03-16 10:21:38,052 INFO: SchoologyLinked startup [in /Users/giladspitzer/PycharmProjects/CAPSTONE/app/__init__.py:58]
2020-03-16 10:36:35,167 INFO: SchoologyLinked startup [in /Users/giladspitzer/PycharmProjects/CAPSTONE/app/__init__.py:58]
