2020-03-12 09:58:53,569 ERROR: Exception on /user/coby [GET] [in /Users/giladspitzer/PycharmProjects/CAPSTONE/venv/lib/python3.8/site-packages/flask/app.py:1890]
Traceback (most recent call last):
  File "/Users/giladspitzer/PycharmProjects/CAPSTONE/venv/lib/python3.8/site-packages/flask/app.py", line 2446, in wsgi_app
    response = self.full_dispatch_request()
  File "/Users/giladspitzer/PycharmProjects/CAPSTONE/venv/lib/python3.8/site-packages/flask/app.py", line 1951, in full_dispatch_request
    rv = self.handle_user_exception(e)
  File "/Users/giladspitzer/PycharmProjects/CAPSTONE/venv/lib/python3.8/site-packages/flask/app.py", line 1820, in handle_user_exception
    reraise(exc_type, exc_value, tb)
  File "/Users/giladspitzer/PycharmProjects/CAPSTONE/venv/lib/python3.8/site-packages/flask/_compat.py", line 39, in reraise
    raise value
  File "/Users/giladspitzer/PycharmProjects/CAPSTONE/venv/lib/python3.8/site-packages/flask/app.py", line 1949, in full_dispatch_request
    rv = self.dispatch_request()
  File "/Users/giladspitzer/PycharmProjects/CAPSTONE/venv/lib/python3.8/site-packages/flask/app.py", line 1935, in dispatch_request
    return self.view_functions[rule.endpoint](**req.view_args)
  File "/Users/giladspitzer/PycharmProjects/CAPSTONE/venv/lib/python3.8/site-packages/flask_login/utils.py", line 272, in decorated_view
    return func(*args, **kwargs)
  File "/Users/giladspitzer/PycharmProjects/CAPSTONE/app/routes.py", line 214, in user
    return render_template("user.html", user=user, comment_form=comment_form, posts=commits.items, next_url=next_url, prev_url=prev_url)
  File "/Users/giladspitzer/PycharmProjects/CAPSTONE/venv/lib/python3.8/site-packages/flask/templating.py", line 138, in render_template
    ctx.app.jinja_env.get_or_select_template(template_name_or_list),
  File "/Users/giladspitzer/PycharmProjects/CAPSTONE/venv/lib/python3.8/site-packages/jinja2/environment.py", line 930, in get_or_select_template
    return self.get_template(template_name_or_list, parent, globals)
  File "/Users/giladspitzer/PycharmProjects/CAPSTONE/venv/lib/python3.8/site-packages/jinja2/environment.py", line 883, in get_template
    return self._load_template(name, self.make_globals(globals))
  File "/Users/giladspitzer/PycharmProjects/CAPSTONE/venv/lib/python3.8/site-packages/jinja2/environment.py", line 857, in _load_template
    template = self.loader.load(self, name, globals)
  File "/Users/giladspitzer/PycharmProjects/CAPSTONE/venv/lib/python3.8/site-packages/jinja2/loaders.py", line 129, in load
    code = environment.compile(source, name, filename)
  File "/Users/giladspitzer/PycharmProjects/CAPSTONE/venv/lib/python3.8/site-packages/jinja2/environment.py", line 638, in compile
    self.handle_exception(source=source_hint)
  File "/Users/giladspitzer/PycharmProjects/CAPSTONE/venv/lib/python3.8/site-packages/jinja2/environment.py", line 832, in handle_exception
    reraise(*rewrite_traceback_stack(source=source))
  File "/Users/giladspitzer/PycharmProjects/CAPSTONE/venv/lib/python3.8/site-packages/jinja2/_compat.py", line 28, in reraise
    raise value.with_traceback(tb)
  File "/Users/giladspitzer/PycharmProjects/CAPSTONE/app/templates/user.html", line 19, in template
    {% if  %}
jinja2.exceptions.TemplateSyntaxError: Expected an expression, got 'end of statement block'
2020-03-12 10:01:25,647 INFO: SchoologyLinked startup [in /Users/giladspitzer/PycharmProjects/CAPSTONE/app/__init__.py:58]
2020-03-12 10:04:32,832 INFO: SchoologyLinked startup [in /Users/giladspitzer/PycharmProjects/CAPSTONE/app/__init__.py:58]
2020-03-12 10:06:01,921 INFO: SchoologyLinked startup [in /Users/giladspitzer/PycharmProjects/CAPSTONE/app/__init__.py:58]
2020-03-12 10:06:17,145 INFO: SchoologyLinked startup [in /Users/giladspitzer/PycharmProjects/CAPSTONE/app/__init__.py:58]
2020-03-12 10:09:08,282 INFO: SchoologyLinked startup [in /Users/giladspitzer/PycharmProjects/CAPSTONE/app/__init__.py:58]
2020-03-12 10:13:51,074 INFO: SchoologyLinked startup [in /Users/giladspitzer/PycharmProjects/CAPSTONE/app/__init__.py:58]
2020-03-12 10:15:00,803 INFO: SchoologyLinked startup [in /Users/giladspitzer/PycharmProjects/CAPSTONE/app/__init__.py:58]
2020-03-12 10:15:12,239 INFO: SchoologyLinked startup [in /Users/giladspitzer/PycharmProjects/CAPSTONE/app/__init__.py:58]
2020-03-12 10:20:51,699 INFO: SchoologyLinked startup [in /Users/giladspitzer/PycharmProjects/CAPSTONE/app/__init__.py:58]
2020-03-12 10:23:03,255 INFO: SchoologyLinked startup [in /Users/giladspitzer/PycharmProjects/CAPSTONE/app/__init__.py:58]
2020-03-12 10:24:55,859 INFO: SchoologyLinked startup [in /Users/giladspitzer/PycharmProjects/CAPSTONE/app/__init__.py:58]
2020-03-12 10:26:23,832 INFO: SchoologyLinked startup [in /Users/giladspitzer/PycharmProjects/CAPSTONE/app/__init__.py:58]
2020-03-12 10:27:22,831 INFO: SchoologyLinked startup [in /Users/giladspitzer/PycharmProjects/CAPSTONE/app/__init__.py:58]
2020-03-12 10:27:38,864 INFO: SchoologyLinked startup [in /Users/giladspitzer/PycharmProjects/CAPSTONE/app/__init__.py:58]
2020-03-12 10:30:38,729 INFO: SchoologyLinked startup [in /Users/giladspitzer/PycharmProjects/CAPSTONE/app/__init__.py:58]
2020-03-12 10:32:03,906 INFO: SchoologyLinked startup [in /Users/giladspitzer/PycharmProjects/CAPSTONE/app/__init__.py:58]
2020-03-12 10:33:40,112 INFO: SchoologyLinked startup [in /Users/giladspitzer/PycharmProjects/CAPSTONE/app/__init__.py:58]
2020-03-12 10:33:48,461 INFO: SchoologyLinked startup [in /Users/giladspitzer/PycharmProjects/CAPSTONE/app/__init__.py:58]
2020-03-12 10:41:50,990 ERROR: Exception on /assignment/None [GET] [in /Users/giladspitzer/PycharmProjects/CAPSTONE/venv/lib/python3.8/site-packages/flask/app.py:1890]
Traceback (most recent call last):
  File "/Users/giladspitzer/PycharmProjects/CAPSTONE/venv/lib/python3.8/site-packages/flask/app.py", line 2446, in wsgi_app
    response = self.full_dispatch_request()
  File "/Users/giladspitzer/PycharmProjects/CAPSTONE/venv/lib/python3.8/site-packages/flask/app.py", line 1951, in full_dispatch_request
    rv = self.handle_user_exception(e)
  File "/Users/giladspitzer/PycharmProjects/CAPSTONE/venv/lib/python3.8/site-packages/flask/app.py", line 1820, in handle_user_exception
    reraise(exc_type, exc_value, tb)
  File "/Users/giladspitzer/PycharmProjects/CAPSTONE/venv/lib/python3.8/site-packages/flask/_compat.py", line 39, in reraise
    raise value
  File "/Users/giladspitzer/PycharmProjects/CAPSTONE/venv/lib/python3.8/site-packages/flask/app.py", line 1949, in full_dispatch_request
    rv = self.dispatch_request()
  File "/Users/giladspitzer/PycharmProjects/CAPSTONE/venv/lib/python3.8/site-packages/flask/app.py", line 1935, in dispatch_request
    return self.view_functions[rule.endpoint](**req.view_args)
  File "/Users/giladspitzer/PycharmProjects/CAPSTONE/venv/lib/python3.8/site-packages/flask_login/utils.py", line 272, in decorated_view
    return func(*args, **kwargs)
  File "/Users/giladspitzer/PycharmProjects/CAPSTONE/app/routes.py", line 116, in wrapper
    course = Assignment.query.filter_by(id=int(kwargs['id'])).first_or_404().section_id
ValueError: invalid literal for int() with base 10: 'None'
2020-03-12 14:14:13,362 ERROR: Exception on /assignment/None [GET] [in /Users/giladspitzer/PycharmProjects/CAPSTONE/venv/lib/python3.8/site-packages/flask/app.py:1890]
Traceback (most recent call last):
  File "/Users/giladspitzer/PycharmProjects/CAPSTONE/venv/lib/python3.8/site-packages/flask/app.py", line 2446, in wsgi_app
    response = self.full_dispatch_request()
  File "/Users/giladspitzer/PycharmProjects/CAPSTONE/venv/lib/python3.8/site-packages/flask/app.py", line 1951, in full_dispatch_request
    rv = self.handle_user_exception(e)
  File "/Users/giladspitzer/PycharmProjects/CAPSTONE/venv/lib/python3.8/site-packages/flask/app.py", line 1820, in handle_user_exception
    reraise(exc_type, exc_value, tb)
  File "/Users/giladspitzer/PycharmProjects/CAPSTONE/venv/lib/python3.8/site-packages/flask/_compat.py", line 39, in reraise
    raise value
  File "/Users/giladspitzer/PycharmProjects/CAPSTONE/venv/lib/python3.8/site-packages/flask/app.py", line 1949, in full_dispatch_request
    rv = self.dispatch_request()
  File "/Users/giladspitzer/PycharmProjects/CAPSTONE/venv/lib/python3.8/site-packages/flask/app.py", line 1935, in dispatch_request
    return self.view_functions[rule.endpoint](**req.view_args)
  File "/Users/giladspitzer/PycharmProjects/CAPSTONE/venv/lib/python3.8/site-packages/flask_login/utils.py", line 272, in decorated_view
    return func(*args, **kwargs)
  File "/Users/giladspitzer/PycharmProjects/CAPSTONE/app/routes.py", line 116, in wrapper
    course = Assignment.query.filter_by(id=int(kwargs['id'])).first_or_404().section_id
ValueError: invalid literal for int() with base 10: 'None'
2020-03-12 16:00:40,887 INFO: SchoologyLinked startup [in /Users/giladspitzer/PycharmProjects/CAPSTONE/app/__init__.py:58]
2020-03-12 16:00:55,368 INFO: SchoologyLinked startup [in /Users/giladspitzer/PycharmProjects/CAPSTONE/app/__init__.py:58]
2020-03-12 16:01:16,709 INFO: SchoologyLinked startup [in /Users/giladspitzer/PycharmProjects/CAPSTONE/app/__init__.py:58]
