2020-03-15 12:25:59,078 ERROR: Exception on /retrieve_data [GET] [in /Users/giladspitzer/PycharmProjects/CAPSTONE/venv/lib/python3.8/site-packages/flask/app.py:1890]
Traceback (most recent call last):
  File "/Users/giladspitzer/PycharmProjects/CAPSTONE/venv/lib/python3.8/site-packages/flask/app.py", line 2446, in wsgi_app
    response = self.full_dispatch_request()
  File "/Users/giladspitzer/PycharmProjects/CAPSTONE/venv/lib/python3.8/site-packages/flask/app.py", line 1952, in full_dispatch_request
    return self.finalize_request(rv)
  File "/Users/giladspitzer/PycharmProjects/CAPSTONE/venv/lib/python3.8/site-packages/flask/app.py", line 1967, in finalize_request
    response = self.make_response(rv)
  File "/Users/giladspitzer/PycharmProjects/CAPSTONE/venv/lib/python3.8/site-packages/flask/app.py", line 2096, in make_response
    raise TypeError(
TypeError: The view function did not return a valid response. The function either returned None or ended without a return statement.
2020-03-15 12:35:29,015 ERROR: Exception on /retrieve_data [GET] [in /Users/giladspitzer/PycharmProjects/CAPSTONE/venv/lib/python3.8/site-packages/flask/app.py:1890]
Traceback (most recent call last):
  File "/Users/giladspitzer/PycharmProjects/CAPSTONE/venv/lib/python3.8/site-packages/flask/app.py", line 2446, in wsgi_app
    response = self.full_dispatch_request()
  File "/Users/giladspitzer/PycharmProjects/CAPSTONE/venv/lib/python3.8/site-packages/flask/app.py", line 1952, in full_dispatch_request
    return self.finalize_request(rv)
  File "/Users/giladspitzer/PycharmProjects/CAPSTONE/venv/lib/python3.8/site-packages/flask/app.py", line 1967, in finalize_request
    response = self.make_response(rv)
  File "/Users/giladspitzer/PycharmProjects/CAPSTONE/venv/lib/python3.8/site-packages/flask/app.py", line 2096, in make_response
    raise TypeError(
TypeError: The view function did not return a valid response. The function either returned None or ended without a return statement.
2020-03-15 12:35:39,840 ERROR: Exception on /retrieve_data [GET] [in /Users/giladspitzer/PycharmProjects/CAPSTONE/venv/lib/python3.8/site-packages/flask/app.py:1890]
Traceback (most recent call last):
  File "/Users/giladspitzer/PycharmProjects/CAPSTONE/venv/lib/python3.8/site-packages/flask/app.py", line 2446, in wsgi_app
    response = self.full_dispatch_request()
  File "/Users/giladspitzer/PycharmProjects/CAPSTONE/venv/lib/python3.8/site-packages/flask/app.py", line 1952, in full_dispatch_request
    return self.finalize_request(rv)
  File "/Users/giladspitzer/PycharmProjects/CAPSTONE/venv/lib/python3.8/site-packages/flask/app.py", line 1967, in finalize_request
    response = self.make_response(rv)
  File "/Users/giladspitzer/PycharmProjects/CAPSTONE/venv/lib/python3.8/site-packages/flask/app.py", line 2096, in make_response
    raise TypeError(
TypeError: The view function did not return a valid response. The function either returned None or ended without a return statement.
2020-03-15 12:36:41,556 INFO: SchoologyLinked startup [in /Users/giladspitzer/PycharmProjects/CAPSTONE/app/__init__.py:58]
2020-03-15 12:45:01,338 ERROR: Exception on /retrieve_data [GET] [in /Users/giladspitzer/PycharmProjects/CAPSTONE/venv/lib/python3.8/site-packages/flask/app.py:1890]
Traceback (most recent call last):
  File "/Users/giladspitzer/PycharmProjects/CAPSTONE/venv/lib/python3.8/site-packages/flask/app.py", line 2446, in wsgi_app
    response = self.full_dispatch_request()
  File "/Users/giladspitzer/PycharmProjects/CAPSTONE/venv/lib/python3.8/site-packages/flask/app.py", line 1951, in full_dispatch_request
    rv = self.handle_user_exception(e)
  File "/Users/giladspitzer/PycharmProjects/CAPSTONE/venv/lib/python3.8/site-packages/flask/app.py", line 1820, in handle_user_exception
    reraise(exc_type, exc_value, tb)
  File "/Users/giladspitzer/PycharmProjects/CAPSTONE/venv/lib/python3.8/site-packages/flask/_compat.py", line 39, in reraise
    raise value
  File "/Users/giladspitzer/PycharmProjects/CAPSTONE/venv/lib/python3.8/site-packages/flask/app.py", line 1949, in full_dispatch_request
    rv = self.dispatch_request()
  File "/Users/giladspitzer/PycharmProjects/CAPSTONE/venv/lib/python3.8/site-packages/flask/app.py", line 1935, in dispatch_request
    return self.view_functions[rule.endpoint](**req.view_args)
  File "/Users/giladspitzer/PycharmProjects/CAPSTONE/venv/lib/python3.8/site-packages/flask_login/utils.py", line 272, in decorated_view
    return func(*args, **kwargs)
  File "/Users/giladspitzer/PycharmProjects/CAPSTONE/app/routes.py", line 333, in retrieve_data
    current_user.update_assignments()
  File "/Users/giladspitzer/PycharmProjects/CAPSTONE/app/models.py", line 197, in update_assignments
    comments = sc.get_assignment_comments([self.api_key, self.api_secret], s.id, a.id)
  File "/Users/giladspitzer/PycharmProjects/CAPSTONE/app/apiclean.py", line 43, in get_assignment_comments
    return authenticate(data[0], data[1]).get_assignment_comments(sectionid, assignmentid)
  File "/Users/giladspitzer/PycharmProjects/CAPSTONE/app/schoologyapi/api.py", line 852, in get_assignment_comments
    return [Assignment(raw) for raw in self._get('sections/%s/assignments/%s/comments' % (section_id, assignment_id))['comment']]
KeyError: 'comment'
2020-03-15 12:45:01,423 ERROR: Exception on /retrieve_data [GET] [in /Users/giladspitzer/PycharmProjects/CAPSTONE/venv/lib/python3.8/site-packages/flask/app.py:1890]
Traceback (most recent call last):
  File "/Users/giladspitzer/PycharmProjects/CAPSTONE/venv/lib/python3.8/site-packages/flask/app.py", line 2446, in wsgi_app
    response = self.full_dispatch_request()
  File "/Users/giladspitzer/PycharmProjects/CAPSTONE/venv/lib/python3.8/site-packages/flask/app.py", line 1951, in full_dispatch_request
    rv = self.handle_user_exception(e)
  File "/Users/giladspitzer/PycharmProjects/CAPSTONE/venv/lib/python3.8/site-packages/flask/app.py", line 1820, in handle_user_exception
    reraise(exc_type, exc_value, tb)
  File "/Users/giladspitzer/PycharmProjects/CAPSTONE/venv/lib/python3.8/site-packages/flask/_compat.py", line 39, in reraise
    raise value
  File "/Users/giladspitzer/PycharmProjects/CAPSTONE/venv/lib/python3.8/site-packages/flask/app.py", line 1949, in full_dispatch_request
    rv = self.dispatch_request()
  File "/Users/giladspitzer/PycharmProjects/CAPSTONE/venv/lib/python3.8/site-packages/flask/app.py", line 1935, in dispatch_request
    return self.view_functions[rule.endpoint](**req.view_args)
  File "/Users/giladspitzer/PycharmProjects/CAPSTONE/venv/lib/python3.8/site-packages/flask_login/utils.py", line 272, in decorated_view
    return func(*args, **kwargs)
  File "/Users/giladspitzer/PycharmProjects/CAPSTONE/app/routes.py", line 333, in retrieve_data
    current_user.update_assignments()
  File "/Users/giladspitzer/PycharmProjects/CAPSTONE/app/models.py", line 201, in update_assignments
    name = person.name_display
AttributeError: 'User' object has no attribute 'name_display'
2020-03-15 12:45:01,617 ERROR: Exception on /retrieve_data [GET] [in /Users/giladspitzer/PycharmProjects/CAPSTONE/venv/lib/python3.8/site-packages/flask/app.py:1890]
Traceback (most recent call last):
  File "/Users/giladspitzer/PycharmProjects/CAPSTONE/venv/lib/python3.8/site-packages/flask/app.py", line 2446, in wsgi_app
    response = self.full_dispatch_request()
  File "/Users/giladspitzer/PycharmProjects/CAPSTONE/venv/lib/python3.8/site-packages/flask/app.py", line 1951, in full_dispatch_request
    rv = self.handle_user_exception(e)
  File "/Users/giladspitzer/PycharmProjects/CAPSTONE/venv/lib/python3.8/site-packages/flask/app.py", line 1820, in handle_user_exception
    reraise(exc_type, exc_value, tb)
  File "/Users/giladspitzer/PycharmProjects/CAPSTONE/venv/lib/python3.8/site-packages/flask/_compat.py", line 39, in reraise
    raise value
  File "/Users/giladspitzer/PycharmProjects/CAPSTONE/venv/lib/python3.8/site-packages/flask/app.py", line 1949, in full_dispatch_request
    rv = self.dispatch_request()
  File "/Users/giladspitzer/PycharmProjects/CAPSTONE/venv/lib/python3.8/site-packages/flask/app.py", line 1935, in dispatch_request
    return self.view_functions[rule.endpoint](**req.view_args)
  File "/Users/giladspitzer/PycharmProjects/CAPSTONE/venv/lib/python3.8/site-packages/flask_login/utils.py", line 272, in decorated_view
    return func(*args, **kwargs)
  File "/Users/giladspitzer/PycharmProjects/CAPSTONE/app/routes.py", line 333, in retrieve_data
    current_user.update_assignments()
  File "/Users/giladspitzer/PycharmProjects/CAPSTONE/app/models.py", line 197, in update_assignments
    comments = sc.get_assignment_comments([self.api_key, self.api_secret], s.id, a.id)
  File "/Users/giladspitzer/PycharmProjects/CAPSTONE/app/apiclean.py", line 43, in get_assignment_comments
    return authenticate(data[0], data[1]).get_assignment_comments(sectionid, assignmentid)
  File "/Users/giladspitzer/PycharmProjects/CAPSTONE/app/schoologyapi/api.py", line 852, in get_assignment_comments
    return [Assignment(raw) for raw in self._get('sections/%s/assignments/%s/comments' % (section_id, assignment_id))['comment']]
KeyError: 'comment'
