2020-02-24 19:45:32,708 ERROR: Exception on /sync [GET] [in /Users/giladspitzer/PycharmProjects/CAPSTONE/venv/lib/python3.8/site-packages/flask/app.py:1890]
Traceback (most recent call last):
  File "/Users/giladspitzer/PycharmProjects/CAPSTONE/venv/lib/python3.8/site-packages/flask/app.py", line 2446, in wsgi_app
    response = self.full_dispatch_request()
  File "/Users/giladspitzer/PycharmProjects/CAPSTONE/venv/lib/python3.8/site-packages/flask/app.py", line 1952, in full_dispatch_request
    return self.finalize_request(rv)
  File "/Users/giladspitzer/PycharmProjects/CAPSTONE/venv/lib/python3.8/site-packages/flask/app.py", line 1967, in finalize_request
    response = self.make_response(rv)
  File "/Users/giladspitzer/PycharmProjects/CAPSTONE/venv/lib/python3.8/site-packages/flask/app.py", line 2096, in make_response
    raise TypeError(
TypeError: The view function did not return a valid response. The function either returned None or ended without a return statement.
2020-02-26 20:44:42,147 INFO: SchoologyLinked startup [in /Users/giladspitzer/PycharmProjects/untitled2/app/__init__.py:58]
2020-02-26 20:44:48,238 ERROR: Exception on /login [POST] [in /Users/giladspitzer/PycharmProjects/untitled2/venv/lib/python3.8/site-packages/flask/app.py:1890]
Traceback (most recent call last):
  File "/Users/giladspitzer/PycharmProjects/untitled2/venv/lib/python3.8/site-packages/sqlalchemy/engine/base.py", line 1245, in _execute_context
    self.dialect.do_execute(
  File "/Users/giladspitzer/PycharmProjects/untitled2/venv/lib/python3.8/site-packages/sqlalchemy/engine/default.py", line 588, in do_execute
    cursor.execute(statement, parameters)
sqlite3.OperationalError: no such table: user

The above exception was the direct cause of the following exception:

Traceback (most recent call last):
  File "/Users/giladspitzer/PycharmProjects/untitled2/venv/lib/python3.8/site-packages/flask/app.py", line 2446, in wsgi_app
    response = self.full_dispatch_request()
  File "/Users/giladspitzer/PycharmProjects/untitled2/venv/lib/python3.8/site-packages/flask/app.py", line 1951, in full_dispatch_request
    rv = self.handle_user_exception(e)
  File "/Users/giladspitzer/PycharmProjects/untitled2/venv/lib/python3.8/site-packages/flask/app.py", line 1820, in handle_user_exception
    reraise(exc_type, exc_value, tb)
  File "/Users/giladspitzer/PycharmProjects/untitled2/venv/lib/python3.8/site-packages/flask/_compat.py", line 39, in reraise
    raise value
  File "/Users/giladspitzer/PycharmProjects/untitled2/venv/lib/python3.8/site-packages/flask/app.py", line 1949, in full_dispatch_request
    rv = self.dispatch_request()
  File "/Users/giladspitzer/PycharmProjects/untitled2/venv/lib/python3.8/site-packages/flask/app.py", line 1935, in dispatch_request
    return self.view_functions[rule.endpoint](**req.view_args)
  File "/Users/giladspitzer/PycharmProjects/untitled2/app/routes.py", line 119, in login
    user = User.query.filter_by(username=form.username.data).first()
  File "/Users/giladspitzer/PycharmProjects/untitled2/venv/lib/python3.8/site-packages/sqlalchemy/orm/query.py", line 3287, in first
    ret = list(self[0:1])
  File "/Users/giladspitzer/PycharmProjects/untitled2/venv/lib/python3.8/site-packages/sqlalchemy/orm/query.py", line 3065, in __getitem__
    return list(res)
  File "/Users/giladspitzer/PycharmProjects/untitled2/venv/lib/python3.8/site-packages/sqlalchemy/orm/query.py", line 3389, in __iter__
    return self._execute_and_instances(context)
  File "/Users/giladspitzer/PycharmProjects/untitled2/venv/lib/python3.8/site-packages/sqlalchemy/orm/query.py", line 3414, in _execute_and_instances
    result = conn.execute(querycontext.statement, self._params)
  File "/Users/giladspitzer/PycharmProjects/untitled2/venv/lib/python3.8/site-packages/sqlalchemy/engine/base.py", line 982, in execute
    return meth(self, multiparams, params)
  File "/Users/giladspitzer/PycharmProjects/untitled2/venv/lib/python3.8/site-packages/sqlalchemy/sql/elements.py", line 293, in _execute_on_connection
    return connection._execute_clauseelement(self, multiparams, params)
  File "/Users/giladspitzer/PycharmProjects/untitled2/venv/lib/python3.8/site-packages/sqlalchemy/engine/base.py", line 1095, in _execute_clauseelement
    ret = self._execute_context(
  File "/Users/giladspitzer/PycharmProjects/untitled2/venv/lib/python3.8/site-packages/sqlalchemy/engine/base.py", line 1249, in _execute_context
    self._handle_dbapi_exception(
  File "/Users/giladspitzer/PycharmProjects/untitled2/venv/lib/python3.8/site-packages/sqlalchemy/engine/base.py", line 1476, in _handle_dbapi_exception
    util.raise_from_cause(sqlalchemy_exception, exc_info)
  File "/Users/giladspitzer/PycharmProjects/untitled2/venv/lib/python3.8/site-packages/sqlalchemy/util/compat.py", line 398, in raise_from_cause
    reraise(type(exception), exception, tb=exc_tb, cause=cause)
  File "/Users/giladspitzer/PycharmProjects/untitled2/venv/lib/python3.8/site-packages/sqlalchemy/util/compat.py", line 152, in reraise
    raise value.with_traceback(tb)
  File "/Users/giladspitzer/PycharmProjects/untitled2/venv/lib/python3.8/site-packages/sqlalchemy/engine/base.py", line 1245, in _execute_context
    self.dialect.do_execute(
  File "/Users/giladspitzer/PycharmProjects/untitled2/venv/lib/python3.8/site-packages/sqlalchemy/engine/default.py", line 588, in do_execute
    cursor.execute(statement, parameters)
sqlalchemy.exc.OperationalError: (sqlite3.OperationalError) no such table: user
[SQL: SELECT user.id AS user_id, user.username AS user_username, user.email AS user_email, user.password_hash AS user_password_hash, user.api_key AS user_api_key, user.api_secret AS user_api_secret, user.outeruid AS user_outeruid, user.about_me AS user_about_me, user.last_seen AS user_last_seen, user.picture_url AS user_picture_url 
FROM user 
WHERE user.username = ?
 LIMIT ? OFFSET ?]
[parameters: ('gilad', 1, 0)]
(Background on this error at: http://sqlalche.me/e/e3q8)
2020-02-26 20:45:03,479 INFO: SchoologyLinked startup [in /Users/giladspitzer/PycharmProjects/untitled2/app/__init__.py:58]
2020-02-26 20:45:07,454 INFO: SchoologyLinked startup [in /Users/giladspitzer/PycharmProjects/untitled2/app/__init__.py:58]
2020-02-26 20:45:10,773 INFO: SchoologyLinked startup [in /Users/giladspitzer/PycharmProjects/untitled2/app/__init__.py:58]
2020-02-26 20:45:42,704 INFO: SchoologyLinked startup [in /Users/giladspitzer/PycharmProjects/untitled2/app/__init__.py:58]
2020-02-26 20:48:51,116 INFO: SchoologyLinked startup [in /Users/giladspitzer/PycharmProjects/CAPSTONE/app/__init__.py:58]
2020-02-26 20:48:57,565 INFO: SchoologyLinked startup [in /Users/giladspitzer/PycharmProjects/CAPSTONE/app/__init__.py:58]
