2020-03-12 22:47:51,899 ERROR: Exception on /sync [GET] [in /Users/giladspitzer/PycharmProjects/CAPSTONE/venv/lib/python3.8/site-packages/flask/app.py:1890]
Traceback (most recent call last):
  File "/Users/giladspitzer/PycharmProjects/CAPSTONE/venv/lib/python3.8/site-packages/sqlalchemy/engine/base.py", line 1245, in _execute_context
    self.dialect.do_execute(
  File "/Users/giladspitzer/PycharmProjects/CAPSTONE/venv/lib/python3.8/site-packages/sqlalchemy/engine/default.py", line 588, in do_execute
    cursor.execute(statement, parameters)
sqlite3.OperationalError: database is locked

The above exception was the direct cause of the following exception:

Traceback (most recent call last):
  File "/Users/giladspitzer/PycharmProjects/CAPSTONE/venv/lib/python3.8/site-packages/flask/app.py", line 2446, in wsgi_app
    response = self.full_dispatch_request()
  File "/Users/giladspitzer/PycharmProjects/CAPSTONE/venv/lib/python3.8/site-packages/flask/app.py", line 1951, in full_dispatch_request
    rv = self.handle_user_exception(e)
  File "/Users/giladspitzer/PycharmProjects/CAPSTONE/venv/lib/python3.8/site-packages/flask/app.py", line 1820, in handle_user_exception
    reraise(exc_type, exc_value, tb)
  File "/Users/giladspitzer/PycharmProjects/CAPSTONE/venv/lib/python3.8/site-packages/flask/_compat.py", line 39, in reraise
    raise value
  File "/Users/giladspitzer/PycharmProjects/CAPSTONE/venv/lib/python3.8/site-packages/flask/app.py", line 1949, in full_dispatch_request
    rv = self.dispatch_request()
  File "/Users/giladspitzer/PycharmProjects/CAPSTONE/venv/lib/python3.8/site-packages/flask/app.py", line 1935, in dispatch_request
    return self.view_functions[rule.endpoint](**req.view_args)
  File "/Users/giladspitzer/PycharmProjects/CAPSTONE/venv/lib/python3.8/site-packages/flask_login/utils.py", line 272, in decorated_view
    return func(*args, **kwargs)
  File "/Users/giladspitzer/PycharmProjects/CAPSTONE/app/routes.py", line 327, in sync
    current_user.update_assignments()
  File "/Users/giladspitzer/PycharmProjects/CAPSTONE/app/models.py", line 173, in update_assignments
    if Assignment.query.filter_by(section_id=s.id, title='Sample Assignment').count() > 0:
  File "/Users/giladspitzer/PycharmProjects/CAPSTONE/venv/lib/python3.8/site-packages/sqlalchemy/orm/query.py", line 3653, in count
    return self.from_self(col).scalar()
  File "/Users/giladspitzer/PycharmProjects/CAPSTONE/venv/lib/python3.8/site-packages/sqlalchemy/orm/query.py", line 3377, in scalar
    ret = self.one()
  File "/Users/giladspitzer/PycharmProjects/CAPSTONE/venv/lib/python3.8/site-packages/sqlalchemy/orm/query.py", line 3347, in one
    ret = self.one_or_none()
  File "/Users/giladspitzer/PycharmProjects/CAPSTONE/venv/lib/python3.8/site-packages/sqlalchemy/orm/query.py", line 3316, in one_or_none
    ret = list(self)
  File "/Users/giladspitzer/PycharmProjects/CAPSTONE/venv/lib/python3.8/site-packages/sqlalchemy/orm/query.py", line 3388, in __iter__
    self.session._autoflush()
  File "/Users/giladspitzer/PycharmProjects/CAPSTONE/venv/lib/python3.8/site-packages/sqlalchemy/orm/session.py", line 1597, in _autoflush
    util.raise_from_cause(e)
  File "/Users/giladspitzer/PycharmProjects/CAPSTONE/venv/lib/python3.8/site-packages/sqlalchemy/util/compat.py", line 398, in raise_from_cause
    reraise(type(exception), exception, tb=exc_tb, cause=cause)
  File "/Users/giladspitzer/PycharmProjects/CAPSTONE/venv/lib/python3.8/site-packages/sqlalchemy/util/compat.py", line 153, in reraise
    raise value
  File "/Users/giladspitzer/PycharmProjects/CAPSTONE/venv/lib/python3.8/site-packages/sqlalchemy/orm/session.py", line 1586, in _autoflush
    self.flush()
  File "/Users/giladspitzer/PycharmProjects/CAPSTONE/venv/lib/python3.8/site-packages/sqlalchemy/orm/session.py", line 2479, in flush
    self._flush(objects)
  File "/Users/giladspitzer/PycharmProjects/CAPSTONE/venv/lib/python3.8/site-packages/sqlalchemy/orm/session.py", line 2617, in _flush
    transaction.rollback(_capture_exception=True)
  File "/Users/giladspitzer/PycharmProjects/CAPSTONE/venv/lib/python3.8/site-packages/sqlalchemy/util/langhelpers.py", line 68, in __exit__
    compat.reraise(exc_type, exc_value, exc_tb)
  File "/Users/giladspitzer/PycharmProjects/CAPSTONE/venv/lib/python3.8/site-packages/sqlalchemy/util/compat.py", line 153, in reraise
    raise value
  File "/Users/giladspitzer/PycharmProjects/CAPSTONE/venv/lib/python3.8/site-packages/sqlalchemy/orm/session.py", line 2577, in _flush
    flush_context.execute()
  File "/Users/giladspitzer/PycharmProjects/CAPSTONE/venv/lib/python3.8/site-packages/sqlalchemy/orm/unitofwork.py", line 422, in execute
    rec.execute(self)
  File "/Users/giladspitzer/PycharmProjects/CAPSTONE/venv/lib/python3.8/site-packages/sqlalchemy/orm/unitofwork.py", line 586, in execute
    persistence.save_obj(
  File "/Users/giladspitzer/PycharmProjects/CAPSTONE/venv/lib/python3.8/site-packages/sqlalchemy/orm/persistence.py", line 239, in save_obj
    _emit_insert_statements(
  File "/Users/giladspitzer/PycharmProjects/CAPSTONE/venv/lib/python3.8/site-packages/sqlalchemy/orm/persistence.py", line 1136, in _emit_insert_statements
    result = cached_connections[connection].execute(
  File "/Users/giladspitzer/PycharmProjects/CAPSTONE/venv/lib/python3.8/site-packages/sqlalchemy/engine/base.py", line 982, in execute
    return meth(self, multiparams, params)
  File "/Users/giladspitzer/PycharmProjects/CAPSTONE/venv/lib/python3.8/site-packages/sqlalchemy/sql/elements.py", line 293, in _execute_on_connection
    return connection._execute_clauseelement(self, multiparams, params)
  File "/Users/giladspitzer/PycharmProjects/CAPSTONE/venv/lib/python3.8/site-packages/sqlalchemy/engine/base.py", line 1095, in _execute_clauseelement
    ret = self._execute_context(
  File "/Users/giladspitzer/PycharmProjects/CAPSTONE/venv/lib/python3.8/site-packages/sqlalchemy/engine/base.py", line 1249, in _execute_context
    self._handle_dbapi_exception(
  File "/Users/giladspitzer/PycharmProjects/CAPSTONE/venv/lib/python3.8/site-packages/sqlalchemy/engine/base.py", line 1476, in _handle_dbapi_exception
    util.raise_from_cause(sqlalchemy_exception, exc_info)
  File "/Users/giladspitzer/PycharmProjects/CAPSTONE/venv/lib/python3.8/site-packages/sqlalchemy/util/compat.py", line 398, in raise_from_cause
    reraise(type(exception), exception, tb=exc_tb, cause=cause)
  File "/Users/giladspitzer/PycharmProjects/CAPSTONE/venv/lib/python3.8/site-packages/sqlalchemy/util/compat.py", line 152, in reraise
    raise value.with_traceback(tb)
  File "/Users/giladspitzer/PycharmProjects/CAPSTONE/venv/lib/python3.8/site-packages/sqlalchemy/engine/base.py", line 1245, in _execute_context
    self.dialect.do_execute(
  File "/Users/giladspitzer/PycharmProjects/CAPSTONE/venv/lib/python3.8/site-packages/sqlalchemy/engine/default.py", line 588, in do_execute
    cursor.execute(statement, parameters)
sqlalchemy.exc.OperationalError: (raised as a result of Query-invoked autoflush; consider using a session.no_autoflush block if this flush is occurring prematurely)
(sqlite3.OperationalError) database is locked
[SQL: INSERT INTO assignment (schoology_id, title, description, due, web_url, section_id, course, img) VALUES (?, ?, ?, ?, ?, ?, ?, ?)]
[parameters: (2386299115, 'Chapter 15 Homework', 'Pg. 530 #(5, 8, 15, 30, 32, 34, 60)', '2020-03-16 23:59:00.000000', 'https://app.schoology.com/assignment/2386299115', 5, 'Advanced Physics (SAS) 01', 'https://api.schoology.com/sites/all/themes/schoology_theme/images/course-default.svg')]
(Background on this error at: http://sqlalche.me/e/e3q8)
